File: Vaango/src/StandAlone/inputs/MPM/TabularModels/DrySandData/DrySand_LoadUnload_45.csv
Dry sand - Load to 45.20% strain then unload to 0 pressure,,,,,
Engineering,,,,,
volumetric,,,,,
strain,pressure,,,,
(%),(MPa),,,,Unload@45.20 strain
0,0,,,,
0.0498753,0.077522,,,,
0.0997506,0.14995,,,,
0.149626,0.22245,,,,
0.199501,0.295023,,,,
0.249377,0.36767,,,,
0.299252,0.44039,,,,
0.349127,0.513185,,,,
0.399002,0.586055,,,,
0.448878,0.659001,,,,
0.498753,0.732022,,,,
0.548628,0.805121,,,,
0.598504,0.878297,,,,
0.648379,0.951552,,,,
0.698254,1.02489,,,,
0.74813,1.0983,,,,
0.798005,1.17179,,,,
0.84788,1.24537,,,,
0.897756,1.31903,,,,
0.947631,1.39277,,,,
0.997506,1.4666,,,,
1.04738,1.54051,,,,
1.09726,1.61452,,,,
1.14713,1.6886,,,,
1.19701,1.76278,,,,
1.24688,1.83705,,,,
1.29676,1.91141,,,,
1.34663,1.98586,,,,
1.39651,2.06041,,,,
1.44638,2.13505,,,,
1.49626,2.20979,,,,
1.54613,2.28462,,,,
1.59601,2.35956,,,,
1.64589,2.4346,,,,
1.69576,2.50974,,,,
1.74564,2.58498,,,,
1.79551,2.66033,,,,
1.84539,2.73578,,,,
1.89526,2.81135,,,,
1.94514,2.88702,,,,
1.99501,2.96281,,,,
2.04489,3.03871,,,,
2.09476,3.11472,,,,
2.14464,3.19085,,,,
2.19451,3.2671,,,,
2.24439,3.34347,,,,
2.29426,3.41997,,,,
2.34414,3.49658,,,,
2.39402,3.57333,,,,
2.44389,3.6502,,,,
2.49377,3.7272,,,,
2.54364,3.80434,,,,
2.59352,3.8816,,,,
2.64339,3.95901,,,,
2.69327,4.03655,,,,
2.74314,4.11423,,,,
2.79302,4.19206,,,,
2.84289,4.27003,,,,
2.89277,4.34815,,,,
2.94264,4.42641,,,,
2.99252,4.50483,,,,
3.04239,4.5834,,,,
3.09227,4.66213,,,,
3.14214,4.74102,,,,
3.19202,4.82007,,,,
3.2419,4.89928,,,,
3.29177,4.97866,,,,
3.34165,5.0582,,,,
3.39152,5.13792,,,,
3.4414,5.21781,,,,
3.49127,5.29788,,,,
3.54115,5.37813,,,,
3.59102,5.45856,,,,
3.6409,5.53917,,,,
3.69077,5.61997,,,,
3.74065,5.70097,,,,
3.79052,5.78215,,,,
3.8404,5.86353,,,,
3.89027,5.94511,,,,
3.94015,6.02689,,,,
3.99003,6.10888,,,,
4.0399,6.19107,,,,
4.08978,6.27347,,,,
4.13965,6.35609,,,,
4.18953,6.43893,,,,
4.2394,6.52198,,,,
4.28928,6.60526,,,,
4.33915,6.68877,,,,
4.38903,6.77251,,,,
4.4389,6.85648,,,,
4.48878,6.94068,,,,
4.53865,7.02513,,,,
4.58853,7.10982,,,,
4.6384,7.19476,,,,
4.68828,7.27995,,,,
4.73815,7.36539,,,,
4.78803,7.45109,,,,
4.83791,7.53705,,,,
4.88778,7.62328,,,,
4.93766,7.70977,,,,
4.98753,7.79654,,,,
5.03741,7.88359,,,,
5.08728,7.97091,,,,
5.13716,8.05852,,,,
5.18703,8.14642,,,,
5.23691,8.23461,,,,
5.28678,8.32309,,,,
5.33666,8.41188,,,,
5.38653,8.50097,,,,
5.43641,8.59037,,,,
5.48628,8.68008,,,,
5.53616,8.77011,,,,
5.58603,8.86045,,,,
5.63591,8.95113,,,,
5.68579,9.04213,,,,
5.73566,9.13347,,,,
5.78554,9.22515,,,,
5.83541,9.31717,,,,
5.88529,9.40953,,,,
5.93516,9.50225,,,,
5.98504,9.59533,,,,
6.03491,9.68876,,,,
6.08479,9.78257,,,,
6.13466,9.87674,,,,
6.18454,9.97129,,,,
6.23441,10.0662,,,,
6.28429,10.1615,,,,
6.33416,10.2572,,,,
6.38404,10.3533,,,,
6.43392,10.4498,,,,
6.48379,10.5468,,,,
6.53367,10.6441,,,,
6.58354,10.7418,,,,
6.63342,10.84,,,,
6.68329,10.9385,,,,
6.73317,11.0376,,,,
6.78304,11.137,,,,
6.83292,11.2369,,,,
6.88279,11.3372,,,,
6.93267,11.438,,,,
6.98254,11.5393,,,,
7.03242,11.641,,,,
7.08229,11.7432,,,,
7.13217,11.8459,,,,
7.18204,11.949,,,,
7.23192,12.0526,,,,
7.2818,12.1568,,,,
7.33167,12.2614,,,,
7.38155,12.3665,,,,
7.43142,12.4722,,,,
7.4813,12.5783,,,,
7.53117,12.685,,,,
7.58105,12.7922,,,,
7.63092,12.9,,,,
7.6808,13.0083,,,,
7.73067,13.1171,,,,
7.78055,13.2265,,,,
7.83042,13.3365,,,,
7.8803,13.447,,,,
7.93017,13.5581,,,,
7.98005,13.6698,,,,
8.02993,13.7821,,,,
8.0798,13.895,,,,
8.12968,14.0084,,,,
8.17955,14.1225,,,,
8.22943,14.2372,,,,
8.2793,14.3525,,,,
8.32918,14.4685,,,,
8.37905,14.5851,,,,
8.42893,14.7023,,,,
8.4788,14.8202,,,,
8.52868,14.9388,,,,
8.57855,15.058,,,,
8.62843,15.1779,,,,
8.6783,15.2984,,,,
8.72818,15.4197,,,,
8.77806,15.5416,,,,
8.82793,15.6643,,,,
8.87781,15.7877,,,,
8.92768,15.9118,,,,
8.97756,16.0366,,,,
9.02743,16.1621,,,,
9.07731,16.2884,,,,
9.12718,16.4155,,,,
9.17706,16.5433,,,,
9.22693,16.6719,,,,
9.27681,16.8012,,,,
9.32668,16.9314,,,,
9.37656,17.0623,,,,
9.42643,17.1941,,,,
9.47631,17.3266,,,,
9.52618,17.46,,,,
9.57606,17.5942,,,,
9.62593,17.7292,,,,
9.67581,17.8651,,,,
9.72569,18.0018,,,,
9.77556,18.1394,,,,
9.82544,18.2779,,,,
9.87531,18.4172,,,,
9.92519,18.5575,,,,
9.97506,18.6986,,,,
10.0499,18.9121,,,,
10.1496,19.1999,,,,
10.2494,19.4914,,,,
10.3491,19.7869,,,,
10.4489,20.0862,,,,
10.5486,20.3896,,,,
10.6484,20.6971,,,,
10.7481,21.0087,,,,
10.8479,21.3246,,,,
10.9476,21.6448,,,,
11.0474,21.9695,,,,
11.1471,22.2987,,,,
11.2469,22.6325,,,,
11.3466,22.971,,,,
11.4464,23.3143,,,,
11.5461,23.6625,,,,
11.6459,24.0157,,,,
11.7456,24.3739,,,,
11.8454,24.7374,,,,
11.9451,25.1061,,,,
12.0449,25.4801,,,,
12.1446,25.8597,,,,
12.2444,26.2449,,,,
12.3441,26.6357,,,,
12.4439,27.0323,,,,
12.5436,27.4349,,,,
12.6434,27.8435,,,,
12.7431,28.2582,,,,
12.8429,28.6791,,,,
12.9426,29.1064,,,,
13.0424,29.5402,,,,
13.1421,29.9806,,,,
13.2419,30.4277,,,,
13.3416,30.8817,,,,
13.4414,31.3426,,,,
13.5411,31.8106,,,,
13.6409,32.2858,,,,
13.7406,32.7684,,,,
13.8404,33.2585,,,,
13.9401,33.7562,,,,
14.0399,34.2616,,,,
14.1397,34.7749,,,,
14.2394,35.2963,,,,
14.3392,35.8258,,,,
14.4389,36.3637,,,,
14.5387,36.91,,,,
14.6384,37.4649,,,,
14.7382,38.0286,,,,
14.8379,38.6012,,,,
14.9377,39.1829,,,,
15.0374,39.7738,,,,
15.1372,40.3741,,,,
15.2369,40.984,,,,
15.3367,41.6035,,,,
15.4364,42.2329,,,,
15.5362,42.8724,,,,
15.6359,43.5221,,,,
15.7357,44.1821,,,,
15.8354,44.8528,,,,
15.9352,45.5342,,,,
16.0349,46.2265,,,,
16.1347,46.9299,,,,
16.2344,47.6446,,,,
16.3342,48.3707,,,,
16.4339,49.1086,,,,
16.5337,49.8583,,,,
16.6334,50.6201,,,,
16.7332,51.3941,,,,
16.8329,52.1806,,,,
16.9327,52.9798,,,,
17.0324,53.7918,,,,
17.1322,54.6169,,,,
17.2319,55.4553,,,,
17.3317,56.3073,,,,
17.4314,57.1729,,,,
17.5312,58.0526,,,,
17.6309,58.9464,,,,
17.7307,59.8546,,,,
17.8304,60.7774,,,,
17.9302,61.7152,,,,
18.0299,62.668,,,,
18.1297,63.6362,,,,
18.2294,64.62,,,,
18.3292,65.6197,,,,
18.4289,66.6354,,,,
18.5287,67.6675,,,,
18.6284,68.7163,,,,
18.7282,69.7819,,,,
18.8279,70.8646,,,,
18.9277,71.9648,,,,
19.0274,73.0826,,,,
19.1272,74.2184,,,,
19.2269,75.3725,,,,
19.3267,76.545,,,,
19.4264,77.7364,,,,
19.5262,78.9469,,,,
19.6259,80.1768,,,,
19.7257,81.4264,,,,
19.8254,82.696,,,,
19.9252,83.986,,,,
20.0249,85.2965,,,,
20.1247,86.628,,,,
20.2244,87.9808,,,,
20.3242,89.3551,,,,
20.4239,90.7514,,,,
20.5237,92.1699,,,,
20.6234,93.6111,,,,
20.7232,95.0751,,,,
20.8229,96.5625,,,,
20.9227,98.0735,,,,
21.0224,99.6085,,,,
21.1222,101.168,,,,
21.2219,102.752,,,,
21.3217,104.361,,,,
21.4214,105.996,,,,
21.5212,107.656,,,,
21.6209,109.343,,,,
21.7207,111.056,,,,
21.8204,112.797,,,,
21.9202,114.565,,,,
22.0199,116.361,,,,
22.1197,118.185,,,,
22.2194,120.037,,,,
22.3192,121.919,,,,
22.419,123.83,,,,
22.5187,125.772,,,,
22.6185,127.743,,,,
22.7182,129.746,,,,
22.818,131.78,,,,
22.9177,133.846,,,,
23.0175,135.944,,,,
23.1172,138.072,,,,
23.217,140.212,,,,
23.3167,142.362,,,,
23.4165,144.521,,,,
23.5162,146.694,,,,
23.616,148.88,,,,
23.7157,151.083,,,,
23.8155,153.302,,,,
23.9152,155.54,,,,
24.015,157.798,,,,
24.1147,160.078,,,,
24.2145,162.381,,,,
24.3142,164.709,,,,
24.414,167.062,,,,
24.5137,169.443,,,,
24.6135,171.853,,,,
24.7132,174.293,,,,
24.813,176.765,,,,
24.9127,179.271,,,,
25.0125,181.811,,,,
25.1122,184.387,,,,
25.212,187.001,,,,
25.3117,189.654,,,,
25.4115,192.348,,,,
25.5112,195.083,,,,
25.611,197.863,,,,
25.7107,200.688,,,,
25.8105,203.559,,,,
25.9102,206.478,,,,
26.01,209.448,,,,
26.1097,212.469,,,,
26.2095,215.542,,,,
26.3092,218.67,,,,
26.409,221.855,,,,
26.5087,225.097,,,,
26.6085,228.399,,,,
26.7082,231.761,,,,
26.808,235.187,,,,
26.9077,238.677,,,,
27.0075,242.233,,,,
27.1072,245.856,,,,
27.207,249.55,,,,
27.3067,253.314,,,,
27.4065,257.152,,,,
27.5062,261.065,,,,
27.606,265.054,,,,
27.7057,269.122,,,,
27.8055,273.27,,,,
27.9052,277.5,,,,
28.005,281.815,,,,
28.1047,286.215,,,,
28.2045,290.704,,,,
28.3042,295.282,,,,
28.404,299.952,,,,
28.5037,304.715,,,,
28.6035,309.575,,,,
28.7032,314.532,,,,
28.803,319.589,,,,
28.9027,324.749,,,,
29.0025,330.012,,,,
29.1022,335.381,,,,
29.202,340.858,,,,
29.3017,346.446,,,,
29.4015,352.147,,,,
29.5012,357.962,,,,
29.601,363.895,,,,
29.7007,369.947,,,,
29.8005,376.12,,,,
29.9002,382.418,,,,
30,388.841,,,,
30.1987,402.022,,,,
30.3974,415.732,,,,
30.5961,429.991,,,,
30.7948,444.819,,,,
30.9935,460.236,,,,
31.1922,476.263,,,,
31.3908,492.922,,,,
31.5895,510.233,,,,
31.7882,528.22,,,,
31.9869,546.905,,,,
32.1856,566.311,,,,
32.3843,586.464,,,,
32.583,607.386,,,,
32.7817,629.104,,,,
32.9804,651.642,,,,
33.1791,675.028,,,,
33.3778,699.288,,,,
33.5765,724.449,,,,
33.7752,750.541,,,,
33.9739,777.591,,,,
34.1726,805.629,,,,
34.3712,834.687,,,,
34.5699,864.794,,,,
34.7686,895.983,,,,
34.9673,928.286,,,,
35.166,961.736,,,,
35.3647,996.368,,,,
35.5634,1032.22,,,,
35.7621,1069.32,,,,
35.9608,1107.71,,,,
36.1595,1147.43,,,,
36.3582,1188.51,,,,
36.5569,1231,,,,
36.7556,1274.93,,,,
36.9542,1320.35,,,,
37.1529,1367.3,,,,
37.3516,1415.83,,,,
37.5503,1465.97,,,,
37.749,1517.77,,,,
37.9477,1571.29,,,,
38.1464,1626.56,,,,
38.3451,1683.64,,,,
38.5438,1742.56,,,,
38.7425,1803.3,,,,
38.9412,1865.89,,,,
39.1399,1930.36,,,,
39.3386,1996.76,,,,
39.5373,2065.1,,,,
39.736,2135.43,,,,
39.9346,2207.77,,,,
40.1333,2282.18,,,,
40.332,2358.67,,,,
40.5307,2437.29,,,,
40.7294,2518.08,,,,
40.9281,2601.08,,,,
41.1268,2686.31,,,,
41.3255,2773.84,,,,
41.5242,2863.68,,,,
41.7229,2955.9,,,,
41.9216,3050.52,,,,
42.1203,3147.59,,,,
42.319,3247.16,,,,
42.5176,3349.28,,,,
42.7163,3453.97,,,,
42.915,3561.3,,,,
43.1137,3671.32,,,,
43.3124,3784.06,,,,
43.5111,3899.58,,,,
43.7098,4017.93,,,,
43.9085,4139.16,,,,
44.1072,4263.32,,,,
44.3059,4390.48,,,,
44.5046,4520.67,,,,
44.7033,4653.96,,,,
44.902,4790.41,,,,
45.1007,4930.07,,,,
45.1975,4999.33,,,,
45.1925,4995.74,,,,
45.1875,4992.16,,,,
45.1825,4988.58,,,,
45.1776,4985,,,,
45.1726,4981.42,,,,
45.1676,4977.85,,,,
45.1626,4974.27,,,,
45.1576,4970.7,,,,
45.1526,4967.13,,,,
45.1476,4963.57,,,,
45.1426,4960,,,,
45.1377,4956.44,,,,
45.1327,4952.88,,,,
45.1277,4949.32,,,,
45.1227,4945.76,,,,
45.1177,4942.21,,,,
45.1127,4938.65,,,,
45.1077,4935.1,,,,
45.1027,4931.56,,,,
45.0978,4928.01,,,,
45.0928,4924.46,,,,
45.0878,4920.92,,,,
45.0828,4917.38,,,,
45.0778,4913.84,,,,
45.0728,4910.31,,,,
45.0678,4906.77,,,,
45.0628,4903.24,,,,
45.0579,4899.71,,,,
45.0529,4896.18,,,,
45.0479,4892.66,,,,
45.0429,4889.13,,,,
45.0379,4885.61,,,,
45.0329,4882.09,,,,
45.0279,4878.58,,,,
45.0229,4875.06,,,,
45.018,4871.55,,,,
45.013,4868.04,,,,
45.008,4864.53,,,,
45.003,4861.02,,,,
44.998,4857.51,,,,
44.993,4854.01,,,,
44.988,4850.51,,,,
44.983,4847.01,,,,
44.9781,4843.51,,,,
44.9731,4840.02,,,,
44.9681,4836.52,,,,
44.9631,4833.03,,,,
44.9581,4829.54,,,,
44.9531,4826.06,,,,
44.9481,4822.57,,,,
44.9431,4819.09,,,,
44.9382,4815.61,,,,
44.9332,4812.13,,,,
44.9282,4808.65,,,,
44.9232,4805.18,,,,
44.9182,4801.71,,,,
44.9132,4798.23,,,,
44.9082,4794.77,,,,
44.9032,4791.3,,,,
44.8983,4787.83,,,,
44.8933,4784.37,,,,
44.8883,4780.91,,,,
44.8833,4777.45,,,,
44.8783,4774,,,,
44.8733,4770.54,,,,
44.8683,4767.09,,,,
44.8633,4763.64,,,,
44.8584,4760.19,,,,
44.8534,4756.74,,,,
44.8484,4753.3,,,,
44.8434,4749.86,,,,
44.8384,4746.42,,,,
44.8334,4742.98,,,,
44.8284,4739.54,,,,
44.8234,4736.11,,,,
44.8185,4732.67,,,,
44.8135,4729.24,,,,
44.8085,4725.82,,,,
44.8035,4722.39,,,,
44.7985,4718.97,,,,
44.7935,4715.54,,,,
44.7885,4712.12,,,,
44.7835,4708.7,,,,
44.7786,4705.29,,,,
44.7736,4701.87,,,,
44.7686,4698.46,,,,
44.7636,4695.05,,,,
44.7586,4691.64,,,,
44.7536,4688.24,,,,
44.7486,4684.83,,,,
44.7436,4681.43,,,,
44.7387,4678.03,,,,
44.7337,4674.63,,,,
44.7287,4671.23,,,,
44.7237,4667.84,,,,
44.7187,4664.45,,,,
44.7137,4661.06,,,,
44.7087,4657.67,,,,
44.7037,4654.28,,,,
44.6988,4650.9,,,,
44.6938,4647.52,,,,
44.6888,4644.14,,,,
44.6838,4640.76,,,,
44.6788,4637.38,,,,
44.6738,4634.01,,,,
44.6688,4630.63,,,,
44.6638,4627.26,,,,
44.6589,4623.89,,,,
44.6539,4620.53,,,,
44.6489,4617.16,,,,
44.6439,4613.8,,,,
44.6389,4610.44,,,,
44.6339,4607.08,,,,
44.6289,4603.72,,,,
44.6239,4600.37,,,,
44.619,4597.02,,,,
44.614,4593.67,,,,
44.609,4590.32,,,,
44.604,4586.97,,,,
44.599,4583.63,,,,
44.594,4580.28,,,,
44.589,4576.94,,,,
44.584,4573.6,,,,
44.5791,4570.27,,,,
44.5741,4566.93,,,,
44.5691,4563.6,,,,
44.5641,4560.27,,,,
44.5591,4556.94,,,,
44.5541,4553.61,,,,
44.5491,4550.29,,,,
44.5441,4546.96,,,,
44.5392,4543.64,,,,
44.5342,4540.32,,,,
44.5292,4537,,,,
44.5242,4533.69,,,,
44.5192,4530.38,,,,
44.5142,4527.06,,,,
44.5092,4523.75,,,,
44.5042,4520.45,,,,
44.4993,4517.14,,,,
44.4943,4513.84,,,,
44.4893,4510.54,,,,
44.4843,4507.24,,,,
44.4793,4503.94,,,,
44.4743,4500.64,,,,
44.4693,4497.35,,,,
44.4643,4494.06,,,,
44.4594,4490.77,,,,
44.4544,4487.48,,,,
44.4494,4484.19,,,,
44.4444,4480.91,,,,
44.4394,4477.63,,,,
44.4344,4474.35,,,,
44.4294,4471.07,,,,
44.4244,4467.79,,,,
44.4195,4464.52,,,,
44.4145,4461.24,,,,
44.4095,4457.97,,,,
44.4045,4454.7,,,,
44.3995,4451.44,,,,
44.3945,4448.17,,,,
44.3895,4444.91,,,,
44.3845,4441.65,,,,
44.3796,4438.39,,,,
44.3746,4435.13,,,,
44.3696,4431.88,,,,
44.3646,4428.62,,,,
44.3596,4425.37,,,,
44.3546,4422.12,,,,
44.3496,4418.88,,,,
44.3446,4415.63,,,,
44.3396,4412.39,,,,
44.3347,4409.14,,,,
44.3297,4405.9,,,,
44.3247,4402.67,,,,
44.3197,4399.43,,,,
44.3147,4396.2,,,,
44.3097,4392.96,,,,
44.3047,4389.73,,,,
44.2998,4386.51,,,,
44.2948,4383.28,,,,
44.2898,4380.06,,,,
44.2848,4376.83,,,,
44.2798,4373.61,,,,
44.2748,4370.39,,,,
44.2698,4367.18,,,,
44.2648,4363.96,,,,
44.2598,4360.75,,,,
44.2549,4357.54,,,,
44.2499,4354.33,,,,
44.2449,4351.12,,,,
44.2399,4347.92,,,,
44.2349,4344.71,,,,
44.2299,4341.51,,,,
44.2249,4338.31,,,,
44.22,4335.11,,,,
44.215,4331.92,,,,
44.21,4328.72,,,,
44.205,4325.53,,,,
44.2,4322.34,,,,
44.1001,4258.85,,,,
44.0002,4196.11,,,,
43.9003,4134.12,,,,
43.8005,4072.88,,,,
43.7006,4012.36,,,,
43.6007,3952.57,,,,
43.5008,3893.51,,,,
43.4009,3835.16,,,,
43.301,3777.51,,,,
43.2011,3720.57,,,,
43.1012,3664.32,,,,
43.0014,3608.77,,,,
42.9015,3553.89,,,,
42.8016,3499.69,,,,
42.7017,3446.17,,,,
42.6018,3393.3,,,,
42.5019,3341.1,,,,
42.402,3289.55,,,,
42.3021,3238.64,,,,
42.2023,3188.38,,,,
42.1024,3138.75,,,,
42.0025,3089.75,,,,
41.9026,3041.38,,,,
41.8027,2993.63,,,,
41.7028,2946.48,,,,
41.6029,2899.95,,,,
41.5031,2854.02,,,,
41.4032,2808.68,,,,
41.3033,2763.94,,,,
41.2034,2719.78,,,,
41.1035,2676.2,,,,
41.0036,2633.2,,,,
40.9037,2590.77,,,,
40.8038,2548.91,,,,
40.704,2507.61,,,,
40.6041,2466.86,,,,
40.5042,2426.67,,,,
40.4043,2387.02,,,,
40.3044,2347.91,,,,
40.2045,2309.34,,,,
40.1046,2271.3,,,,
40.0047,2233.79,,,,
39.9049,2196.8,,,,
39.805,2160.33,,,,
39.7051,2124.37,,,,
39.6052,2088.92,,,,
39.5053,2053.98,,,,
39.4054,2019.54,,,,
39.3055,1985.59,,,,
39.2057,1952.13,,,,
39.1058,1919.16,,,,
39.0059,1886.68,,,,
38.906,1854.67,,,,
38.8061,1823.14,,,,
38.7062,1792.07,,,,
38.6063,1761.48,,,,
38.5064,1731.34,,,,
38.4066,1701.67,,,,
38.3067,1672.29,,,,
38.2068,1643.01,,,,
38.1069,1613.83,,,,
38.007,1584.74,,,,
37.9071,1555.75,,,,
37.8072,1526.85,,,,
37.7073,1498.05,,,,
37.6075,1469.34,,,,
37.5076,1440.73,,,,
37.4077,1412.21,,,,
37.3078,1383.79,,,,
37.2079,1355.46,,,,
37.108,1327.22,,,,
37.0081,1299.07,,,,
36.9082,1271.02,,,,
36.8084,1243.06,,,,
36.7085,1215.18,,,,
36.6086,1187.4,,,,
36.5087,1159.71,,,,
36.4088,1132.11,,,,
36.3089,1104.6,,,,
36.209,1077.18,,,,
36.1092,1049.84,,,,
36.0093,1022.6,,,,
35.9094,995.443,,,,
35.8095,968.374,,,,
35.7096,941.393,,,,
35.6097,914.499,,,,
35.5098,887.693,,,,
35.4099,860.972,,,,
35.3101,834.338,,,,
35.2102,807.79,,,,
35.1103,781.328,,,,
35.0104,754.951,,,,
34.9105,728.659,,,,
34.8106,702.452,,,,
34.7107,676.33,,,,
34.6108,650.292,,,,
34.511,624.338,,,,
34.4111,598.468,,,,
34.3112,572.682,,,,
34.2113,546.979,,,,
34.1114,521.36,,,,
34.0115,495.824,,,,
33.9116,470.371,,,,
33.8118,445.002,,,,
33.7119,419.715,,,,
33.612,394.511,,,,
33.5121,369.39,,,,
33.4122,344.353,,,,
33.3123,319.398,,,,
33.2124,294.527,,,,
33.1125,269.74,,,,
33.0127,245.037,,,,
32.9128,220.419,,,,
32.8129,195.887,,,,
32.713,171.441,,,,
32.6131,147.084,,,,
32.5132,122.817,,,,
32.4133,98.6436,,,,
32.3134,74.5686,,,,
32.2136,50.6003,,,,
32.1137,26.7558,,,,
32.0138,3.09663,,,,