File: Vaango/src/StandAlone/inputs/MPM/TabularModels/DrySandData/DrySand_LoadUnload_18.csv
Dry sand - Load to 18.08% strain then unload to 0 pressure,,,,,
Engineering,,,,,
volumetric,,,,,
strain,pressure,,,,
(%),(MPa),,,,Unload@18.08 strain
0,0,,,,
0.0249377,0.0413353,,,,
0.0498753,0.077522,,,,
0.074813,0.113727,,,,
0.0997506,0.14995,,,,
0.124688,0.186191,,,,
0.149626,0.22245,,,,
0.174564,0.258727,,,,
0.199501,0.295023,,,,
0.224439,0.331337,,,,
0.249377,0.36767,,,,
0.274314,0.404021,,,,
0.299252,0.44039,,,,
0.32419,0.476778,,,,
0.349127,0.513185,,,,
0.374065,0.549611,,,,
0.399002,0.586055,,,,
0.42394,0.622518,,,,
0.448878,0.659001,,,,
0.473815,0.695502,,,,
0.498753,0.732022,,,,
0.523691,0.768562,,,,
0.548628,0.805121,,,,
0.573566,0.841699,,,,
0.598504,0.878297,,,,
0.623441,0.914914,,,,
0.648379,0.951552,,,,
0.673317,0.988209,,,,
0.698254,1.02489,,,,
0.723192,1.06158,,,,
0.74813,1.0983,,,,
0.773067,1.13504,,,,
0.798005,1.17179,,,,
0.822943,1.20857,,,,
0.84788,1.24537,,,,
0.872818,1.28219,,,,
0.897756,1.31903,,,,
0.922693,1.35589,,,,
0.947631,1.39277,,,,
0.972569,1.42968,,,,
0.997506,1.4666,,,,
1.02244,1.50355,,,,
1.04738,1.54051,,,,
1.07232,1.5775,,,,
1.09726,1.61452,,,,
1.12219,1.65155,,,,
1.14713,1.6886,,,,
1.17207,1.72568,,,,
1.19701,1.76278,,,,
1.22195,1.7999,,,,
1.24688,1.83705,,,,
1.27182,1.87422,,,,
1.29676,1.91141,,,,
1.3217,1.94862,,,,
1.34663,1.98586,,,,
1.37157,2.02312,,,,
1.39651,2.06041,,,,
1.42145,2.09772,,,,
1.44638,2.13505,,,,
1.47132,2.17241,,,,
1.49626,2.20979,,,,
1.5212,2.24719,,,,
1.54613,2.28462,,,,
1.57107,2.32208,,,,
1.59601,2.35956,,,,
1.62095,2.39707,,,,
1.64589,2.4346,,,,
1.67082,2.47215,,,,
1.69576,2.50974,,,,
1.7207,2.54735,,,,
1.74564,2.58498,,,,
1.77057,2.62264,,,,
1.79551,2.66033,,,,
1.82045,2.69804,,,,
1.84539,2.73578,,,,
1.87032,2.77355,,,,
1.89526,2.81135,,,,
1.9202,2.84917,,,,
1.94514,2.88702,,,,
1.97007,2.9249,,,,
1.99501,2.96281,,,,
2.01995,3.00074,,,,
2.04489,3.03871,,,,
2.06983,3.0767,,,,
2.09476,3.11472,,,,
2.1197,3.15277,,,,
2.14464,3.19085,,,,
2.16958,3.22896,,,,
2.19451,3.2671,,,,
2.21945,3.30527,,,,
2.24439,3.34347,,,,
2.26933,3.38171,,,,
2.29426,3.41997,,,,
2.3192,3.45826,,,,
2.34414,3.49658,,,,
2.36908,3.53494,,,,
2.39402,3.57333,,,,
2.41895,3.61175,,,,
2.44389,3.6502,,,,
2.46883,3.68868,,,,
2.49377,3.7272,,,,
2.5187,3.76575,,,,
2.54364,3.80434,,,,
2.56858,3.84295,,,,
2.59352,3.8816,,,,
2.61845,3.92029,,,,
2.64339,3.95901,,,,
2.66833,3.99776,,,,
2.69327,4.03655,,,,
2.7182,4.07537,,,,
2.74314,4.11423,,,,
2.76808,4.15313,,,,
2.79302,4.19206,,,,
2.81796,4.23103,,,,
2.84289,4.27003,,,,
2.86783,4.30907,,,,
2.89277,4.34815,,,,
2.91771,4.38726,,,,
2.94264,4.42641,,,,
2.96758,4.4656,,,,
2.99252,4.50483,,,,
3.01746,4.5441,,,,
3.04239,4.5834,,,,
3.06733,4.62275,,,,
3.09227,4.66213,,,,
3.11721,4.70156,,,,
3.14214,4.74102,,,,
3.16708,4.78052,,,,
3.19202,4.82007,,,,
3.21696,4.85965,,,,
3.2419,4.89928,,,,
3.26683,4.93895,,,,
3.29177,4.97866,,,,
3.31671,5.01841,,,,
3.34165,5.0582,,,,
3.36658,5.09804,,,,
3.39152,5.13792,,,,
3.41646,5.17785,,,,
3.4414,5.21781,,,,
3.46633,5.25783,,,,
3.49127,5.29788,,,,
3.51621,5.33798,,,,
3.54115,5.37813,,,,
3.56608,5.41832,,,,
3.59102,5.45856,,,,
3.61596,5.49884,,,,
3.6409,5.53917,,,,
3.66584,5.57955,,,,
3.69077,5.61997,,,,
3.71571,5.66045,,,,
3.74065,5.70097,,,,
3.76559,5.74153,,,,
3.79052,5.78215,,,,
3.81546,5.82281,,,,
3.8404,5.86353,,,,
3.86534,5.90429,,,,
3.89027,5.94511,,,,
3.91521,5.98597,,,,
3.94015,6.02689,,,,
3.96509,6.06786,,,,
3.99003,6.10888,,,,
4.01496,6.14995,,,,
4.0399,6.19107,,,,
4.06484,6.23225,,,,
4.08978,6.27347,,,,
4.11471,6.31476,,,,
4.13965,6.35609,,,,
4.16459,6.39748,,,,
4.18953,6.43893,,,,
4.21446,6.48043,,,,
4.2394,6.52198,,,,
4.26434,6.5636,,,,
4.28928,6.60526,,,,
4.31421,6.64699,,,,
4.33915,6.68877,,,,
4.36409,6.73061,,,,
4.38903,6.77251,,,,
4.41396,6.81446,,,,
4.4389,6.85648,,,,
4.46384,6.89855,,,,
4.48878,6.94068,,,,
4.51372,6.98288,,,,
4.53865,7.02513,,,,
4.56359,7.06744,,,,
4.58853,7.10982,,,,
4.61347,7.15226,,,,
4.6384,7.19476,,,,
4.66334,7.23732,,,,
4.68828,7.27995,,,,
4.71322,7.32264,,,,
4.73815,7.36539,,,,
4.76309,7.40821,,,,
4.78803,7.45109,,,,
4.81297,7.49404,,,,
4.83791,7.53705,,,,
4.86284,7.58013,,,,
4.88778,7.62328,,,,
4.91272,7.66649,,,,
4.93766,7.70977,,,,
4.96259,7.75312,,,,
4.98753,7.79654,,,,
5.01247,7.84003,,,,
5.03741,7.88359,,,,
5.06234,7.92721,,,,
5.08728,7.97091,,,,
5.11222,8.01468,,,,
5.13716,8.05852,,,,
5.1621,8.10243,,,,
5.18703,8.14642,,,,
5.21197,8.19048,,,,
5.23691,8.23461,,,,
5.26185,8.27881,,,,
5.28678,8.32309,,,,
5.31172,8.36745,,,,
5.33666,8.41188,,,,
5.3616,8.45639,,,,
5.38653,8.50097,,,,
5.41147,8.54563,,,,
5.43641,8.59037,,,,
5.46135,8.63518,,,,
5.48628,8.68008,,,,
5.51122,8.72505,,,,
5.53616,8.77011,,,,
5.5611,8.81524,,,,
5.58603,8.86045,,,,
5.61097,8.90575,,,,
5.63591,8.95113,,,,
5.66085,8.99659,,,,
5.68579,9.04213,,,,
5.71072,9.08776,,,,
5.73566,9.13347,,,,
5.7606,9.17927,,,,
5.78554,9.22515,,,,
5.81047,9.27111,,,,
5.83541,9.31717,,,,
5.86035,9.36331,,,,
5.88529,9.40953,,,,
5.91022,9.45585,,,,
5.93516,9.50225,,,,
5.9601,9.54874,,,,
5.98504,9.59533,,,,
6.00997,9.642,,,,
6.03491,9.68876,,,,
6.05985,9.73562,,,,
6.08479,9.78257,,,,
6.10973,9.82961,,,,
6.13466,9.87674,,,,
6.1596,9.92397,,,,
6.18454,9.97129,,,,
6.20948,10.0187,,,,
6.23441,10.0662,,,,
6.25935,10.1138,,,,
6.28429,10.1615,,,,
6.30923,10.2093,,,,
6.33416,10.2572,,,,
6.3591,10.3052,,,,
6.38404,10.3533,,,,
6.40898,10.4015,,,,
6.43392,10.4498,,,,
6.45885,10.4982,,,,
6.48379,10.5468,,,,
6.50873,10.5954,,,,
6.53367,10.6441,,,,
6.5586,10.6929,,,,
6.58354,10.7418,,,,
6.60848,10.7908,,,,
6.63342,10.84,,,,
6.65835,10.8892,,,,
6.68329,10.9385,,,,
6.70823,10.988,,,,
6.73317,11.0376,,,,
6.7581,11.0872,,,,
6.78304,11.137,,,,
6.80798,11.1869,,,,
6.83292,11.2369,,,,
6.85786,11.287,,,,
6.88279,11.3372,,,,
6.90773,11.3876,,,,
6.93267,11.438,,,,
6.95761,11.4886,,,,
6.98254,11.5393,,,,
7.00748,11.5901,,,,
7.03242,11.641,,,,
7.05736,11.692,,,,
7.08229,11.7432,,,,
7.10723,11.7945,,,,
7.13217,11.8459,,,,
7.15711,11.8974,,,,
7.18204,11.949,,,,
7.20698,12.0008,,,,
7.23192,12.0526,,,,
7.25686,12.1046,,,,
7.2818,12.1568,,,,
7.30673,12.209,,,,
7.33167,12.2614,,,,
7.35661,12.3139,,,,
7.38155,12.3665,,,,
7.40648,12.4193,,,,
7.43142,12.4722,,,,
7.45636,12.5252,,,,
7.4813,12.5783,,,,
7.50623,12.6316,,,,
7.53117,12.685,,,,
7.55611,12.7386,,,,
7.58105,12.7922,,,,
7.60598,12.846,,,,
7.63092,12.9,,,,
7.65586,12.9541,,,,
7.6808,13.0083,,,,
7.70574,13.0626,,,,
7.73067,13.1171,,,,
7.75561,13.1717,,,,
7.78055,13.2265,,,,
7.80549,13.2814,,,,
7.83042,13.3365,,,,
7.85536,13.3917,,,,
7.8803,13.447,,,,
7.90524,13.5025,,,,
7.93017,13.5581,,,,
7.95511,13.6139,,,,
7.98005,13.6698,,,,
8.00499,13.7259,,,,
8.02993,13.7821,,,,
8.05486,13.8384,,,,
8.0798,13.895,,,,
8.10474,13.9516,,,,
8.12968,14.0084,,,,
8.15461,14.0654,,,,
8.17955,14.1225,,,,
8.20449,14.1798,,,,
8.22943,14.2372,,,,
8.25436,14.2948,,,,
8.2793,14.3525,,,,
8.30424,14.4104,,,,
8.32918,14.4685,,,,
8.35411,14.5267,,,,
8.37905,14.5851,,,,
8.40399,14.6436,,,,
8.42893,14.7023,,,,
8.45387,14.7612,,,,
8.4788,14.8202,,,,
8.50374,14.8794,,,,
8.52868,14.9388,,,,
8.55362,14.9983,,,,
8.57855,15.058,,,,
8.60349,15.1178,,,,
8.62843,15.1779,,,,
8.65337,15.2381,,,,
8.6783,15.2984,,,,
8.70324,15.359,,,,
8.72818,15.4197,,,,
8.75312,15.4806,,,,
8.77806,15.5416,,,,
8.80299,15.6029,,,,
8.82793,15.6643,,,,
8.85287,15.7259,,,,
8.87781,15.7877,,,,
8.90274,15.8496,,,,
8.92768,15.9118,,,,
8.95262,15.9741,,,,
8.97756,16.0366,,,,
9.00249,16.0993,,,,
9.02743,16.1621,,,,
9.05237,16.2252,,,,
9.07731,16.2884,,,,
9.10224,16.3519,,,,
9.12718,16.4155,,,,
9.15212,16.4793,,,,
9.17706,16.5433,,,,
9.20199,16.6075,,,,
9.22693,16.6719,,,,
9.25187,16.7365,,,,
9.27681,16.8012,,,,
9.30175,16.8662,,,,
9.32668,16.9314,,,,
9.35162,16.9968,,,,
9.37656,17.0623,,,,
9.4015,17.1281,,,,
9.42643,17.1941,,,,
9.45137,17.2602,,,,
9.47631,17.3266,,,,
9.50125,17.3932,,,,
9.52618,17.46,,,,
9.55112,17.527,,,,
9.57606,17.5942,,,,
9.601,17.6616,,,,
9.62593,17.7292,,,,
9.65087,17.797,,,,
9.67581,17.8651,,,,
9.70075,17.9334,,,,
9.72569,18.0018,,,,
9.75062,18.0705,,,,
9.77556,18.1394,,,,
9.8005,18.2086,,,,
9.82544,18.2779,,,,
9.85037,18.3475,,,,
9.87531,18.4172,,,,
9.90025,18.4873,,,,
9.92519,18.5575,,,,
9.95012,18.628,,,,
9.97506,18.6986,,,,
10,18.7696,,,,
10.0499,18.9121,,,,
10.0998,19.0555,,,,
10.1496,19.1999,,,,
10.1995,19.3452,,,,
10.2494,19.4915,,,,
10.2993,19.6387,,,,
10.3491,19.7869,,,,
10.399,19.9361,,,,
10.4489,20.0863,,,,
10.4988,20.2375,,,,
10.5486,20.3897,,,,
10.5985,20.5429,,,,
10.6484,20.6971,,,,
10.6983,20.8524,,,,
10.7481,21.0088,,,,
10.798,21.1662,,,,
10.8479,21.3247,,,,
10.8978,21.4842,,,,
10.9477,21.6449,,,,
10.9975,21.8067,,,,
11.0474,21.9696,,,,
11.0973,22.1336,,,,
11.1472,22.2988,,,,
11.197,22.4651,,,,
11.2469,22.6326,,,,
11.2968,22.8013,,,,
11.3467,22.9711,,,,
11.3965,23.1422,,,,
11.4464,23.3144,,,,
11.4963,23.4879,,,,
11.5462,23.6626,,,,
11.596,23.8386,,,,
11.6459,24.0158,,,,
11.6958,24.1943,,,,
11.7457,24.3741,,,,
11.7956,24.5551,,,,
11.8454,24.7375,,,,
11.8953,24.9212,,,,
11.9452,25.1062,,,,
11.9951,25.2926,,,,
12.0449,25.4803,,,,
12.0948,25.6694,,,,
12.1447,25.8599,,,,
12.1946,26.0518,,,,
12.2444,26.2451,,,,
12.2943,26.4398,,,,
12.3442,26.6359,,,,
12.3941,26.8335,,,,
12.444,27.0326,,,,
12.4938,27.2331,,,,
12.5437,27.4351,,,,
12.5936,27.6387,,,,
12.6435,27.8437,,,,
12.6933,28.0503,,,,
12.7432,28.2584,,,,
12.7931,28.4681,,,,
12.843,28.6794,,,,
12.8928,28.8923,,,,
12.9427,29.1067,,,,
12.9926,29.3228,,,,
13.0425,29.5405,,,,
13.0923,29.7599,,,,
13.1422,29.9809,,,,
13.1921,30.2037,,,,
13.242,30.4281,,,,
13.2919,30.6542,,,,
13.3417,30.882,,,,
13.3916,31.1116,,,,
13.4415,31.343,,,,
13.4914,31.5761,,,,
13.5412,31.811,,,,
13.5911,32.0477,,,,
13.641,32.2863,,,,
13.6909,32.5266,,,,
13.7407,32.7689,,,,
13.7906,33.013,,,,
13.8405,33.2589,,,,
13.8904,33.5068,,,,
13.9402,33.7567,,,,
13.9901,34.0084,,,,
14.04,34.2621,,,,
14.0899,34.5178,,,,
14.1398,34.7755,,,,
14.1896,35.0351,,,,
14.2395,35.2969,,,,
14.2894,35.5606,,,,
14.3393,35.8264,,,,
14.3891,36.0943,,,,
14.439,36.3643,,,,
14.4889,36.6364,,,,
14.5388,36.9106,,,,
14.5886,37.187,,,,
14.6385,37.4656,,,,
14.6884,37.7463,,,,
14.7383,38.0293,,,,
14.7881,38.3145,,,,
14.838,38.6019,,,,
14.8879,38.8916,,,,
14.9378,39.1836,,,,
14.9877,39.4779,,,,
15.0375,39.7746,,,,
15.0874,40.0735,,,,
15.1373,40.3749,,,,
15.1872,40.6786,,,,
15.237,40.9848,,,,
15.2869,41.2933,,,,
15.3368,41.6043,,,,
15.3867,41.9178,,,,
15.4365,42.2338,,,,
15.4864,42.5523,,,,
15.5363,42.8733,,,,
15.5862,43.1968,,,,
15.636,43.523,,,,
15.6859,43.8517,,,,
15.7358,44.1831,,,,
15.7857,44.5171,,,,
15.8356,44.8538,,,,
15.8854,45.1931,,,,
15.9353,45.5352,,,,
15.9852,45.88,,,,
16.0351,46.2275,,,,
16.0849,46.5778,,,,
16.1348,46.9309,,,,
16.1847,47.2869,,,,
16.2346,47.6457,,,,
16.2844,48.0073,,,,
16.3343,48.3719,,,,
16.3842,48.7394,,,,
16.4341,49.1098,,,,
16.484,49.4831,,,,
16.5338,49.8595,,,,
16.5837,50.2389,,,,
16.6336,50.6213,,,,
16.6835,51.0068,,,,
16.7333,51.3954,,,,
16.7832,51.7871,,,,
16.8331,52.1819,,,,
16.883,52.5799,,,,
16.9328,52.9811,,,,
16.9827,53.3856,,,,
17.0326,53.7932,,,,
17.0825,54.2042,,,,
17.1323,54.6184,,,,
17.1822,55.0359,,,,
17.2321,55.4568,,,,
17.282,55.8811,,,,
17.3319,56.3088,,,,
17.3817,56.7399,,,,
17.4316,57.1745,,,,
17.4815,57.6126,,,,
17.5314,58.0542,,,,
17.5812,58.4993,,,,
17.6311,58.9481,,,,
17.681,59.4004,,,,
17.7309,59.8563,,,,
17.7807,60.3159,,,,
17.8306,60.7792,,,,
17.8805,61.2463,,,,
17.9304,61.717,,,,
17.9802,62.1916,,,,
18.0301,62.6699,,,,
18.08,63.1521,,,,
18.0775,63.0063,,,,
18.075,62.8608,,,,
18.0725,62.7156,,,,
18.07,62.5708,,,,
18.0675,62.4264,,,,
18.065,62.2822,,,,
18.0625,62.1384,,,,
18.06,61.995,,,,
18.0576,61.8519,,,,
18.0551,61.7091,,,,
18.0526,61.5666,,,,
18.0501,61.4245,,,,
18.0476,61.2827,,,,
18.0451,61.1413,,,,
18.0426,61.0001,,,,
18.0401,60.8593,,,,
18.0376,60.7189,,,,
18.0351,60.5788,,,,
18.0326,60.439,,,,
18.0301,60.2995,,,,
18.0276,60.1603,,,,
18.0251,60.0215,,,,
18.0226,59.883,,,,
18.0201,59.7449,,,,
18.0177,59.607,,,,
18.0152,59.4695,,,,
18.0127,59.3323,,,,
18.0102,59.1955,,,,
18.0077,59.0589,,,,
18.0052,58.9227,,,,
18.0027,58.7868,,,,
18.0002,58.6512,,,,
17.9977,58.516,,,,
17.9952,58.381,,,,
17.9927,58.2464,,,,
17.9902,58.1121,,,,
17.9877,57.9781,,,,
17.9852,57.8445,,,,
17.9827,57.7111,,,,
17.9802,57.5781,,,,
17.9778,57.4454,,,,
17.9753,57.313,,,,
17.9728,57.1809,,,,
17.9703,57.0491,,,,
17.9678,56.9176,,,,
17.9653,56.7865,,,,
17.9628,56.6556,,,,
17.9603,56.5251,,,,
17.9578,56.3948,,,,
17.9553,56.2649,,,,
17.9528,56.1353,,,,
17.9503,56.006,,,,
17.9478,55.877,,,,
17.9453,55.7484,,,,
17.9428,55.62,,,,
17.9403,55.4919,,,,
17.9379,55.3641,,,,
17.9354,55.2367,,,,
17.9329,55.1095,,,,
17.9304,54.9826,,,,
17.9279,54.8561,,,,
17.9254,54.7298,,,,
17.9229,54.6039,,,,
17.9204,54.4782,,,,
17.9179,54.3529,,,,
17.9154,54.2278,,,,
17.9129,54.1031,,,,
17.9104,53.9786,,,,
17.9079,53.8544,,,,
17.9054,53.7306,,,,
17.9029,53.607,,,,
17.9004,53.4837,,,,
17.898,53.3607,,,,
17.8955,53.238,,,,
17.893,53.1157,,,,
17.8905,52.9936,,,,
17.888,52.8717,,,,
17.8855,52.7502,,,,
17.883,52.629,,,,
17.8805,52.5081,,,,
17.878,52.3874,,,,
17.8755,52.2671,,,,
17.873,52.147,,,,
17.8705,52.0272,,,,
17.868,51.9077,,,,
17.8655,51.7885,,,,
17.863,51.6696,,,,
17.8605,51.551,,,,
17.8581,51.4326,,,,
17.8556,51.3146,,,,
17.8531,51.1968,,,,
17.8506,51.0793,,,,
17.8481,50.9621,,,,
17.8456,50.8451,,,,
17.8431,50.7285,,,,
17.8406,50.6121,,,,
17.8381,50.496,,,,
17.8356,50.3802,,,,
17.8331,50.2647,,,,
17.8306,50.1494,,,,
17.8281,50.0345,,,,
17.8256,49.9198,,,,
17.8231,49.8053,,,,
17.8206,49.6912,,,,
17.8182,49.5773,,,,
17.8157,49.4637,,,,
17.8132,49.3504,,,,
17.8107,49.2374,,,,
17.8082,49.1246,,,,
17.8057,49.0121,,,,
17.8032,48.8998,,,,
17.8007,48.7879,,,,
17.7982,48.6762,,,,
17.7957,48.5648,,,,
17.7932,48.4536,,,,
17.7907,48.3428,,,,
17.7882,48.2321,,,,
17.7857,48.1218,,,,
17.7832,48.0117,,,,
17.7807,47.9019,,,,
17.7783,47.7924,,,,
17.7758,47.6831,,,,
17.7733,47.5741,,,,
17.7708,47.4653,,,,
17.7683,47.3568,,,,
17.7658,47.2486,,,,
17.7633,47.1407,,,,
17.7608,47.033,,,,
17.7583,46.9255,,,,
17.7558,46.8184,,,,
17.7533,46.7114,,,,
17.7508,46.6048,,,,
17.7483,46.4984,,,,
17.7458,46.3923,,,,
17.7433,46.2864,,,,
17.7408,46.1808,,,,
17.7384,46.0754,,,,
17.7359,45.9703,,,,
17.7334,45.8654,,,,
17.7309,45.7608,,,,
17.7284,45.6565,,,,
17.7259,45.5524,,,,
17.7234,45.4486,,,,
17.7209,45.345,,,,
17.7184,45.2417,,,,
17.7159,45.1386,,,,
17.7134,45.0358,,,,
17.7109,44.9332,,,,
17.7084,44.8309,,,,
17.7059,44.7288,,,,
17.7034,44.627,,,,
17.7009,44.5254,,,,
17.6985,44.4241,,,,
17.696,44.323,,,,
17.6935,44.2221,,,,
17.691,44.1216,,,,
17.6885,44.0212,,,,
17.686,43.9211,,,,
17.6835,43.8213,,,,
17.681,43.7217,,,,
17.6785,43.6223,,,,
17.676,43.5232,,,,
17.6735,43.4243,,,,
17.671,43.3257,,,,
17.6685,43.2273,,,,
17.666,43.1291,,,,
17.6635,43.0312,,,,
17.661,42.9335,,,,
17.6586,42.8361,,,,
17.6561,42.7389,,,,
17.6536,42.642,,,,
17.6511,42.5453,,,,
17.6486,42.4488,,,,
17.6461,42.3525,,,,
17.6436,42.2565,,,,
17.6411,42.1608,,,,
17.6386,42.0652,,,,
17.6361,41.9699,,,,
17.6336,41.8748,,,,
17.6311,41.78,,,,
17.6286,41.6854,,,,
17.6261,41.591,,,,
17.6236,41.4969,,,,
17.6211,41.403,,,,
17.6187,41.3093,,,,
17.6162,41.2159,,,,
17.6137,41.1227,,,,
17.6112,41.0297,,,,
17.6087,40.9369,,,,
17.6062,40.8444,,,,
17.6037,40.7521,,,,
17.6012,40.6601,,,,
17.5987,40.5682,,,,
17.5962,40.4766,,,,
17.5937,40.3852,,,,
17.5912,40.294,,,,
17.5887,40.2031,,,,
17.5862,40.1124,,,,
17.5837,40.0219,,,,
17.5812,39.9316,,,,
17.5788,39.8416,,,,
17.5763,39.7517,,,,
17.5738,39.6621,,,,
17.5713,39.5728,,,,
17.5688,39.4836,,,,
17.5663,39.3946,,,,
17.5638,39.3059,,,,
17.5613,39.2174,,,,
17.5588,39.1291,,,,
17.5563,39.0411,,,,
17.5538,38.9532,,,,
17.5513,38.8656,,,,
17.5488,38.7782,,,,
17.5463,38.691,,,,
17.5438,38.604,,,,
17.5413,38.5172,,,,
17.5389,38.4307,,,,
17.5364,38.3443,,,,
17.5339,38.2582,,,,
17.5314,38.1723,,,,
17.5289,38.0866,,,,
17.5264,38.0011,,,,
17.5239,37.9159,,,,
17.5214,37.8308,,,,
17.5189,37.7459,,,,
17.5164,37.6613,,,,
17.5139,37.5769,,,,
17.5114,37.4926,,,,
17.5089,37.4086,,,,
17.5064,37.3248,,,,
17.5039,37.2412,,,,
17.5014,37.1578,,,,
17.499,37.0746,,,,
17.4965,36.9917,,,,
17.494,36.9089,,,,
17.4915,36.8263,,,,
17.489,36.744,,,,
17.4865,36.6618,,,,
17.484,36.5799,,,,
17.4815,36.4981,,,,
17.479,36.4166,,,,
17.4765,36.3352,,,,
17.474,36.2541,,,,
17.4715,36.1731,,,,
17.469,36.0924,,,,
17.4665,36.0119,,,,
17.464,35.9315,,,,
17.4615,35.8514,,,,
17.4591,35.7714,,,,
17.4566,35.6917,,,,
17.4541,35.6122,,,,
17.4516,35.5328,,,,
17.4491,35.4537,,,,
17.4466,35.3747,,,,
17.4441,35.296,,,,
17.4416,35.2174,,,,
17.4391,35.139,,,,
17.4366,35.0609,,,,
17.4341,34.9829,,,,
17.4316,34.9051,,,,
17.4291,34.8275,,,,
17.4266,34.7501,,,,
17.4241,34.6729,,,,
17.4216,34.5959,,,,
17.4192,34.5191,,,,
17.4167,34.4425,,,,
17.4142,34.3661,,,,
17.4117,34.2898,,,,
17.4092,34.2138,,,,
17.4067,34.1379,,,,
17.4042,34.0622,,,,
17.4017,33.9867,,,,
17.3992,33.9114,,,,
17.3967,33.8363,,,,
17.3942,33.7614,,,,
17.3917,33.6867,,,,
17.3892,33.6121,,,,
17.3867,33.5378,,,,
17.3842,33.4636,,,,
17.3817,33.3896,,,,
17.3793,33.3158,,,,
17.3768,33.2421,,,,
17.3743,33.1687,,,,
17.3718,33.0954,,,,
17.3693,33.0224,,,,
17.3668,32.9495,,,,
17.3643,32.8768,,,,
17.3618,32.8042,,,,
17.3593,32.7319,,,,
17.3568,32.6597,,,,
17.3543,32.5877,,,,
17.3518,32.5159,,,,
17.3493,32.4443,,,,
17.3468,32.3728,,,,
17.3443,32.3016,,,,
17.3418,32.2305,,,,
17.3394,32.1595,,,,
17.3369,32.0888,,,,
17.3344,32.0182,,,,
17.3319,31.9479,,,,
17.3294,31.8776,,,,
17.3269,31.8076,,,,
17.3244,31.7377,,,,
17.3219,31.6681,,,,
17.3194,31.5985,,,,
17.3169,31.5292,,,,
17.3144,31.46,,,,
17.3119,31.391,,,,
17.3094,31.3222,,,,
17.3069,31.2536,,,,
17.3044,31.1851,,,,
17.3019,31.1168,,,,
17.2995,31.0486,,,,
17.297,30.9807,,,,
17.2945,30.9129,,,,
17.292,30.8452,,,,
17.2895,30.7778,,,,
17.287,30.7105,,,,
17.2845,30.6434,,,,
17.282,30.5764,,,,
17.2795,30.5096,,,,
17.277,30.443,,,,
17.2745,30.3765,,,,
17.272,30.3103,,,,
17.2695,30.2441,,,,
17.267,30.1782,,,,
17.2645,30.1124,,,,
17.262,30.0467,,,,
17.2596,29.9813,,,,
17.2571,29.916,,,,
17.2546,29.8508,,,,
17.2521,29.7859,,,,
17.2496,29.721,,,,
17.2471,29.6564,,,,
17.2446,29.5919,,,,
17.2421,29.5276,,,,
17.2396,29.4634,,,,
17.2371,29.3994,,,,
17.2346,29.3355,,,,
17.2321,29.2718,,,,
17.2296,29.2083,,,,
17.2271,29.1449,,,,
17.2246,29.0817,,,,
17.2221,29.0187,,,,
17.2197,28.9558,,,,
17.2172,28.893,,,,
17.2147,28.8304,,,,
17.2122,28.768,,,,
17.2097,28.7057,,,,
17.2072,28.6436,,,,
17.2047,28.5816,,,,
17.2022,28.5198,,,,
17.1997,28.4582,,,,
17.1972,28.3967,,,,
17.1947,28.3353,,,,
17.1922,28.2741,,,,
17.1897,28.2131,,,,
17.1872,28.1522,,,,
17.1847,28.0915,,,,
17.1822,28.0309,,,,
17.1798,27.9704,,,,
17.1773,27.9101,,,,
17.1748,27.85,,,,
17.1723,27.79,,,,
17.1698,27.7302,,,,
17.1673,27.6705,,,,
17.1648,27.6109,,,,
17.1623,27.5516,,,,
17.1598,27.4923,,,,
17.1573,27.4332,,,,
17.1548,27.3743,,,,
17.1523,27.3155,,,,
17.1498,27.2568,,,,
17.1473,27.1983,,,,
17.1448,27.1399,,,,
17.1423,27.0817,,,,
17.1399,27.0236,,,,
17.1374,26.9657,,,,
17.1349,26.9079,,,,
17.1324,26.8503,,,,
17.1299,26.7928,,,,
17.1274,26.7354,,,,
17.1249,26.6782,,,,
17.1224,26.6211,,,,
17.1199,26.5642,,,,
17.1174,26.5074,,,,
17.1149,26.4508,,,,
17.1124,26.3943,,,,
17.1099,26.3379,,,,
17.1074,26.2817,,,,
17.1049,26.2256,,,,
17.1024,26.1696,,,,
17.0999,26.1138,,,,
17.0975,26.0582,,,,
17.095,26.0026,,,,
17.0925,25.9472,,,,
17.09,25.892,,,,
17.0875,25.8369,,,,
17.085,25.7819,,,,
17.0825,25.727,,,,
17.08,25.6723,,,,
17.0301,24.6047,,,,
16.9801,23.5886,,,,
16.9302,22.6212,,,,
16.8802,21.6998,,,,
16.8303,20.822,,,,
16.7804,19.9853,,,,
16.7304,19.1872,,,,
16.6805,18.4255,,,,
16.6305,17.6981,,,,
16.5806,17.0027,,,,
16.5306,16.3375,,,,
16.4807,15.7005,,,,
16.4308,15.0899,,,,
16.3808,14.5038,,,,
16.3309,13.9407,,,,
16.2809,13.399,,,,
16.231,12.877,,,,
16.1811,12.3734,,,,
16.1311,11.8868,,,,
16.0812,11.4158,,,,
16.0312,10.9593,,,,
15.9813,10.5161,,,,
15.9313,10.085,,,,
15.8814,9.66508,,,,
15.8315,9.25529,,,,
15.7815,8.85472,,,,
15.7316,8.46251,,,,
15.6816,8.07785,,,,
15.6317,7.69999,,,,
15.5818,7.32823,,,,
15.5318,6.96192,,,,
15.4819,6.60046,,,,
15.4319,6.2433,,,,
15.382,5.88993,,,,
15.332,5.53988,,,,
15.2821,5.19273,,,,
15.2322,4.84811,,,,
15.1822,4.50567,,,,
15.1323,4.1651,,,,
15.0823,3.82614,,,,
15.0324,3.48854,,,,
14.9825,3.1521,,,,
14.9325,2.81665,,,,
14.8826,2.48203,,,,
14.8326,2.14812,,,,
14.7827,1.81482,,,,
14.7327,1.48206,,,,
14.6828,1.14977,,,,
14.6329,0.817909,,,,
14.5829,0.48646,,,,
14.533,0.155403,,,,